Workbook

Sheet Кошторис
A1: Кошторис будівництва під ключ — СЕС на даху АБК, ТОВ МК «Антарес», інвертор Deye SUN-100K-G03 (100 кВт), DC до 1000 В
A2: Два варіанти: «Як є» — розкладка К1 з доміком на надбудові; «ДБН» — з драбинами П1, огородженням 0,6 м і ходовими доріжками. $ без ПДВ. Синій — вихідні дані, чорний — формули, зелений — з аркуша «Параметри».
A4: № | B4: Позиція | C4: Од. | D4: К-сть «Як є» | E4: К-сть «ДБН» | F4: Ціна, $ | G4: Мито | H4: Сума «Як є», $ | I4: Сума «ДБН», $ | J4: Підстава
A5: 1. Закупівля в Китаї, FOB — разом із замовленням СЕС цеху
A6: 1.1 | B6: Фотомодулі ZNSHINE ZXN8-BD132-730 (730 Вт, з виводами 1,2–1,4 м), з запасом 2 % | C6: шт | D6: =Параметри!B10 -> 146 | E6: =Параметри!C10 -> 135 | F6: =Параметри!$B$30 -> 73 | G6: 0 | H6: =D6*F6 -> 10658 | I6: =E6*F6 -> 9855 | J6: кошторис під ключ 27.10, поз. 1.2
A7: 1.2 | B7: Кріплення на арці по даху: лаги, гільзи, шпильки, профілі, кутники, притиски, метизи | C7: модуль | D7: =Параметри!B5 -> 95 | E7: =Параметри!C5 -> 86 | F7: =Параметри!$B$31 -> 11.168831 | G7: 0.008 | H7: =D7*F7 -> 1061.039 | I7: =E7*F7 -> 960.51948 | J7: КП 26.10, на модуль
A8: 1.3 | B8: Кріплення «домік» схід–захід 15° на нижньому даху і надбудові: профілі, кронштейни, притиски, метизи | C8: модуль | D8: =Параметри!B6+Параметри!B7 -> 39 | E8: =Параметри!C6+Параметри!C7 -> 37 | F8: =Параметри!$B$32 -> 10.897619 | G8: 0.008 | H8: =D8*F8 -> 425.00714 | I8: =E8*F8 -> 403.2119 | J8: розрахунок ГалКат 15° 22.10, на модуль
A9: 1.4 | B9: Кріплення на південних стінах: рейки, кронштейни з анкерами, притиски | C9: модуль | D9: =Параметри!B8 -> 9 | E9: =Параметри!C8 -> 9 | F9: =Параметри!$B$33 -> 8.6026936 | G9: 0.008 | H9: =D9*F9 -> 77.424242 | I9: =E9*F9 -> 77.424242 | J9: кошторис під ключ 27.10, поз. 1.3.2, на модуль
A10: 1.5 | B10: Кабелі DC H1Z2Z2-K 1×6 мм² (≈686 м), роз'єми MC4, металорукав | C10: стрінг | D10: =Параметри!B12 -> 11 | E10: =Параметри!C12 -> 11 | F10: =Параметри!$B$34 -> 60 | G10: 0.067 | H10: =D10*F10 -> 660 | I10: =E10*F10 -> 660 | J10: кошторис під ключ 27.10, поз. 1.4, на стрінг
A11: 1.6 | B11: Лотки з кришками, фасонні, кріплення | C11: стрінг | D11: =Параметри!B12 -> 11 | E11: =Параметри!C12 -> 11 | F11: =Параметри!$B$35 -> 64.572917 | G11: 0.001 | H11: =D11*F11 -> 710.30208 | I11: =E11*F11 -> 710.30208 | J11: кошторис під ключ 27.10, поз. 1.7, на стрінг
A12: 1.7 | B12: Блискавкозахист: ПЗІП, провідники, затискачі | C12: модуль | D12: =Параметри!B9 -> 143 | E12: =Параметри!C9 -> 132 | F12: =Параметри!$B$36 -> 1.1363636 | G12: 0.05 | H12: =D12*F12 -> 162.5 | I12: =E12*F12 -> 150 | J12: кошторис під ключ 27.10, поз. 1.8, на модуль
A13: 1.8 | B13: Кабель RS485 2×2×0,75 в екрані — лічильник на вводі АБК → інвертор | C13: м | D13: =Параметри!B18 -> 55 | E13: =Параметри!C18 -> 55 | F13: =Параметри!$B$37 -> 0.26285714 | G13: 0.1 | H13: =D13*F13 -> 14.457143 | I13: =E13*F13 -> 14.457143 | J13: специфікація Китай 26.10
B14: Разом закупівля в Китаї | H14: =SUM(H6:H13) -> 13768.73 | I14: =SUM(I6:I13) -> 12830.915
A15: 2. Наша комісія — супровід замовлення за договором комісії
A16: 2.1 | B16: Комісія від закупівлі в Китаї | F16: =Параметри!$B$38 -> 0.05 | H16: =H14*F16 -> 688.43648 | I16: =I14*F16 -> 641.54574 | J16: договір комісії
B17: Разом комісія | H17: =H16 -> 688.43648 | I17: =I16 -> 641.54574
A18: 3. Доставка до об'єкта, страхування, мито
A19: 3.1 | B19: Доставка модулів у контейнерах 40'HQ (594 модулі в контейнері) | C19: шт | D19: =Параметри!B10 -> 146 | E19: =Параметри!C10 -> 135 | F19: =Параметри!$B$39 -> 11.784512 | H19: =D19*F19 -> 1720.5387 | I19: =E19*F19 -> 1590.9091 | J19: кошторис під ключ 27.10, поз. 3.2
A20: 3.2 | B20: Доставка кріплення, кабелів і лотків (частка контейнерів 40'HQ) | C20: модуль | D20: =Параметри!B9 -> 143 | E20: =Параметри!C9 -> 132 | F20: =Параметри!$B$40 -> 6.6287879 | H20: =D20*F20 -> 947.91667 | I20: =E20*F20 -> 875 | J20: кошторис під ключ 27.10, поз. 3.3
A21: 3.3 | B21: Страхування вантажу, крім модулів | F21: =Параметри!$B$41 -> 0.003 | H21: =(H14-H6)*F21 -> 9.3321887 | I21: =(I14-I6)*F21 -> 8.9277446 | J21: кошторис під ключ 27.10
A22: 3.4 | B22: Мито на товари, крім модулів (модулі — пільга «245») | F22: =Параметри!$B$42 -> 1.1431332 | H22: =SUMPRODUCT(G6:G13,H6:H13)*F22 -> 76.599959 | I22: =SUMPRODUCT(G6:G13,I6:I13)*F22 -> 74.766925 | J22: ставки мита за кодами УКТ ЗЕД, як у кошторисі 27.10
B23: Разом доставка і мито | H23: =SUM(H19:H22) -> 2754.3875 | I23: =SUM(I19:I22) -> 2549.6038
A24: 4. Купуємо в Україні: інвертор, підключення, баласт, безпека покрівлі
A25: 4.1 | B25: Інвертор мережевий Deye SUN-100K-G03: 100 кВт, 3 фази 400 В, 6 MPPT, DC до 1000 В, IP65; DC-роз'єднувач, ПЗІП тип II на DC і AC | C25: шт | D25: 1 | E25: 1 | F25: =Параметри!$B$57/(1+Параметри!$B$54)/Параметри!$B$28 -> 2595.7711 | H25: =D25*F25 -> 2595.7711 | I25: =E25*F25 -> 2595.7711 | J25: 220volt.com.ua, 28.10.2026, у наявності
A26: 4.2 | B26: Баластний блок 300×300×60 з муфтою і матом — під лаги арки, «домік», опори лотків (+1 %) | C26: шт | D26: =Параметри!B16 -> 513 | E26: =Параметри!C16 -> 476 | F26: =Параметри!$B$43 -> 3 | H26: =D26*F26 -> 1539 | I26: =E26*F26 -> 1428 | J26: рішення власника 26.10
A27: 4.3 | B27: Кабель ВВГнг 5×70 мм², мідь — інвертор → вступний щит АБК | C27: м | D27: =Параметри!B17 -> 45 | E27: =Параметри!C17 -> 45 | F27: =Параметри!$B$58/(1+Параметри!$B$54)/Параметри!$B$28 -> 59.854459 | H27: =D27*F27 -> 2693.4507 | I27: =E27*F27 -> 2693.4507 | J27: amperia.com.ua, 28.10.2026, у наявності
A28: 4.4 | B28: Щит СЕС біля вступного щита АБК: автоматичний вимикач 3P 200 А в корпусі IP54 | C28: компл | D28: 1 | E28: 1 | F28: =Параметри!$B$59/(1+Параметри!$B$54)/Параметри!$B$28+Параметри!$B$60/(1+Параметри!$B$54)/Параметри!$B$28 -> 296.62917 | H28: =D28*F28 -> 296.62917 | I28: =E28*F28 -> 296.62917 | J28: electroelan.dp.ua, 28.10.2026; 220volt.com.ua, 28.10.2026
A29: 4.5 | B29: Лічильник CHINT DTSU666 з трансформаторами струму 250 А на вводі АБК — обмеження видачі в мережу (Zero Export) | C29: компл | D29: 1 | E29: 1 | F29: =Параметри!$B$61/(1+Параметри!$B$54)/Параметри!$B$28 -> 131.72941 | H29: =D29*F29 -> 131.72941 | I29: =E29*F29 -> 131.72941 | J29: hotline.ua (Технопоставка), 28.10.2026
A30: 4.6 | B30: Доставка матеріалів України на об'єкт | C30: блок | D30: =Параметри!B16 -> 513 | E30: =Параметри!C16 -> 476 | F30: =Параметри!$B$47 -> 0.33836518 | H30: =D30*F30 -> 173.58134 | I30: =E30*F30 -> 161.06183 | J30: кошторис під ключ 27.10, поз. 4.9, на блок
A31: 4.7 | B31: Драбина П1 на арку з поручнями над парапетом | C31: м | D31: =Параметри!B19 -> 0 | E31: =Параметри!C19 -> 5.8 | F31: =Параметри!$B$62/(1+Параметри!$B$54)/Параметри!$B$28 -> 167.07507 | H31: =D31*F31 -> 0 | I31: =E31*F31 -> 969.03542 | J31: flagma.ua (ПП «Ліга», Київ), 28.10.2026
A32: 4.8 | B32: Площадка з огорожею 0,6 м на арці перед виходом на покрівлю | C32: шт | D32: =Параметри!B20 -> 0 | E32: =Параметри!C20 -> 1 | F32: 0 | H32: =D32*F32 -> 0 | I32: =E32*F32 -> 0 | J32: ціна — за КП виробника драбини (поки немає)
A33: 4.9 | B33: Драбини П1 на надбудову сходів (2 шт.) | C33: м | D33: =Параметри!B21 -> 0 | E33: =Параметри!C21 -> 5.6 | F33: =Параметри!$B$62/(1+Параметри!$B$54)/Параметри!$B$28 -> 167.07507 | H33: =D33*F33 -> 0 | I33: =E33*F33 -> 935.62041 | J33: flagma.ua (ПП «Ліга», Київ), 28.10.2026
A34: 4.10 | B34: Огородження покрівлі 0,6 м, металеве | C34: м | D34: =Параметри!B22 -> 0 | E34: =Параметри!C22 -> 99 | F34: =Параметри!$B$63/(1+Параметри!$B$54)/Параметри!$B$28 -> 13.324237 | H34: =D34*F34 -> 0 | I34: =E34*F34 -> 1319.0995 | J34: prom.ua (Профі Фасад), 28.10.2026
A35: 4.11 | B35: Ходові доріжки 0,8 м — гумові плити 500×500×20 мм | C35: м² | D35: =Параметри!B23 -> 0 | E35: =Параметри!C23 -> 63 | F35: =Параметри!$B$64/(1+Параметри!$B$54)/Параметри!$B$28 -> 20.234648 | H35: =D35*F35 -> 0 | I35: =E35*F35 -> 1274.7828 | J35: reziplit.in.ua, 28.10.2026
B36: Разом купуємо в Україні | H36: =SUM(H25:H35) -> 7430.1617 | I36: =SUM(I25:I35) -> 11805.18
A37: 5. Роботи
A38: 5.1 | B38: Встановлення і наладка СЕС, електромонтажні роботи DC і AC, налаштування нульового експорту | C38: кВтп | D38: =Параметри!B11 -> 104.39 | E38: =Параметри!C11 -> 96.36 | F38: =Параметри!$B$48 -> 50 | H38: =D38*F38 -> 5219.5 | I38: =E38*F38 -> 4818 | J38: рішення власника 26.10
A39: 5.2 | B39: Механізація: автокран і автовишка | C39: модуль | D39: =Параметри!B9 -> 143 | E39: =Параметри!C9 -> 132 | F39: =Параметри!$B$49 -> 1.4583333 | H39: =D39*F39 -> 208.54167 | I39: =E39*F39 -> 192.5 | J39: кошторис під ключ 27.10, поз. 5.2, на модуль
A40: 5.3 | B40: Витратні матеріали: наконечники, маркування, стяжки, ЗІЗ, вивезення упаковки | C40: модуль | D40: =Параметри!B9 -> 143 | E40: =Параметри!C9 -> 132 | F40: =Параметри!$B$50 -> 1.2234848 | H40: =D40*F40 -> 174.95833 | I40: =E40*F40 -> 161.5 | J40: кошторис під ключ 27.10, поз. 5.8, на модуль
A41: 5.4 | B41: Монтаж драбин П1, огородження з анкеруванням стійок до парапету, укладання доріжок | C41: люд.·год | D41: =Параметри!B24 -> 0 | E41: =Параметри!C24 -> 112 | F41: =Параметри!$B$51/Параметри!$B$28 -> 15.593673 | H41: =D41*F41 -> 0 | I41: =E41*F41 -> 1746.4914 | J41: 700 грн/люд.·год; трудомісткість — аркуш «Параметри»
...

Sheet Параметри
A1: Параметри кошторису СЕС АБК — інвертор Deye SUN-100K-G03, 28.10.2026
A2: Синій — вихідні дані (можна змінювати), чорний — формули. $ без ПДВ, якщо не сказано інше.
A4: Кількості за варіантами | B4: «Як є» | C4: «ДБН» | D4: Од. | E4: Джерело
A5: Модулів на арці основного блоку (по даху, лаги на баласті) | B5: 95 | C5: 86 | D5: шт | E5: 3D-модель АБК 28.10: «Як є» — розкладка К1; «ДБН» — з ходовими доріжками
A6: Модулів на нижньому даху («домік» схід–захід 15°) | B6: 33 | C6: 31 | D6: шт | E6: 33 місця; у «ДБН» 2 місця не добирають стрінга
A7: Модулів на надбудові сходів («домік» 15°) | B7: 6 | C7: 6 | D7: шт | E7: пн. частина 2 + пд. частина 4
A8: Модулів на південних стінах (вертикально) | B8: 9 | C8: 9 | D8: шт | E8: 3D-модель АБК 28.10
A9: Модулів у стрінгах разом | B9: =B5+B6+B7+B8 -> 143 | C9: =C5+C6+C7+C8 -> 132 | D9: шт
A10: Модулів до поставки (+2 %) | B10: =ROUNDUP(B9*$B$29,0) -> 146 | C10: =ROUNDUP(C9*$B$29,0) -> 135 | D10: шт | E10: запас як у кошторисі 27.10
A11: Потужність СЕС, DC | B11: =B9*$B$27/1000 -> 104.39 | C11: =C9*$B$27/1000 -> 96.36 | D11: кВтп | E11: 730 Вт × модулів
A12: Стрінгів | B12: 11 | C12: 11 | D12: шт | E12: по 2 на MPPT, 6 MPPT (аркуш «Стрінги»)
A13: Модулів у стрінгу | B13: 13 | C13: 12 | D13: шт | E13: Voc при −30 °C ≤ 1000 В; найбільша генерація при ≤ 12 стрінгах
A14: Кабель DC 1×6 від стрінгів до інвертора, «+» і «−» | B14: 686 | C14: 688 | D14: м | E14: траса по даху до інвертора, +10 %, +4 м на вводи
A15: Генерація модулів за рік (DC) | B15: 94.4 | C15: 87.1 | D15: МВт·год | E15: повна модель K1: Meteonorm 8.1, тіні DSM 0,25 м, байпас-діоди
A16: Баластних блоків до замовлення (+1 %) | B16: =ROUNDUP((B5*$B$44+(B6+B7)*$B$45+B12*$B$46)*1.01,0) -> 513 | C16: =ROUNDUP((C5*$B$44+(C6+C7)*$B$45+C12*$B$46)*1.01,0) -> 476 | D16: шт | E16: арка — як дах цеху; «домік» — 4 на модуль; опори лотків
A17: Кабель AC інвертор → вступний щит АБК | B17: 45 | C17: 45 | D17: м | E17: з нижнього даху (+10,0) по стіні до вступного щита, +10 %
A18: Кабель RS485 лічильник → інвертор | B18: 55 | C18: 55 | D18: м | E18: вздовж кабелю AC
A19: Драбина П1 на арку: перепад 4,8 м + поручні 1,0 м над парапетом | B19: 0 | C19: 5.8 | D19: м | E19: ДБН В.1.1-7:2016 п. 8.8–8.10; 3D-модель АБК
A20: Площадка з огорожею 0,6 м на арці перед виходом на покрівлю | B20: 0 | C20: 1 | D20: шт | E20: ДБН В.1.1-7:2016 табл. 5
A21: Драбини П1 на надбудову: 2,25 + 1,0 м і 1,35 + 1,0 м (з поручнями над парапетом) | B21: 0 | C21: 5.6 | D21: м | E21: ДБН В.1.1-7:2016 п. 8.8; 3D-модель АБК
A22: Огородження покрівлі 0,6 м: захід і торці арки, парапети надбудови | B22: 0 | C22: 99 | D22: м | E22: ДБН В.1.1-7:2016 п. 8.12, ДБН В.2.6-220:2017 п. 6.1.2; 3D-модель АБК
A23: Ходові доріжки 0,8 м: арка (2 доріжки + зв'язка) і прохід на нижньому даху | B23: 0 | C23: 63 | D23: м² | E23: ДБН В.2.6-220:2017 п. 7.1.3; 3D-модель АБК
A24: Монтаж драбин, площадки, огородження і доріжок | B24: 0 | C24: 112 | D24: люд.·год | E24: драбини 2 × 16, огородження 99 м — 64 (стійки з анкерами через 1,2 м), доріжки 16; трудомісткість E-Systems
A26: Ставки і ціни | B26: Значення | D26: Од. | E26: Джерело
A27: Потужність модуля ZNSHINE ZXN8-BD132-730 | B27: 730 | D27: Вт | E27: паспорт ZNSHINE
A28: Курс | B28: 44.89 | D28: грн/$ | E28: як у розрахунку генерації і кошторисі 27.10
A29: Запас модулів | B29: 1.02 | E29: кошторис під ключ 27.10
A30: Фотомодуль ZNSHINE ZXN8-BD132-730, FOB | B30: 73 | D30: $/шт | E30: кошторис під ключ 27.10, поз. 1.2 (КП ES-261026-01)
A31: Кріплення по даху на баласті, на модуль | B31: =21500/1925 -> 11.168831 | D31: $/модуль | E31: КП 26.10: 21 500 $ на 1 925 модулів (лаги, гільзи, шпильки, профілі, кутники, притиски, метизи)
A32: Кріплення «домік» / трикутники 15°, на модуль | B32: =11211/1260+4*0.5 -> 10.897619 | D32: $/модуль | E32: розрахунок ГалКат 15° 22.10: 11 211 $ на 1 260 модулів + 4 притиски по 0,50 $
A33: Кріплення на стіні: рейки, кронштейни, притиски, на модуль | B33: =2555/297 -> 8.6026936 | D33: $/модуль | E33: кошторис під ключ 27.10, поз. 1.3.2 (рейки, притиски, кронштейни ліхтарів): 2 555 $ на 297 модулів
A34: Кабелі DC 1×6, MC4, металорукав, на стрінг | B34: =11520/192 -> 60 | D34: $/стрінг | E34: кошторис під ключ 27.10, поз. 1.4: 11 520 $ на 192 стрінги
A35: Лотки, кришки, фасонні, кріплення, на стрінг | B35: =12398/192 -> 64.572917 | D35: $/стрінг | E35: кошторис під ключ 27.10, поз. 1.7: 12 398 $ на 192 стрінги
A36: Блискавкозахист: ПЗІП, провідники, затискачі, на модуль | B36: =2400/2112 -> 1.1363636 | D36: $/модуль | E36: кошторис під ключ 27.10, поз. 1.8: 2 400 $ на 2 112 модулів
A37: Кабель RS485 2×2×0,75 в екрані, FOB | B37: =276/1050 -> 0.26285714 | D37: $/м | E37: специфікація замовлення в Китаї 26.10: 276 $ FOB за 1 050 м
A38: Наша комісія від закупівлі в Китаї | B38: 0.05 | E38: договір комісії
A39: Доставка модулів: 40'HQ Шанхай → об'єкт / 594 модулі | B39: =7000/594 -> 11.784512 | D39: $/шт | E39: кошторис під ключ 27.10, поз. 3.2
A40: Доставка кріплення, кабелів, лотків, на модуль | B40: =14000/2112 -> 6.6287879 | D40: $/модуль | E40: кошторис під ключ 27.10, поз. 3.3: 2 контейнери на 2 112 модулів
A41: Страхування вантажу, крім модулів | B41: 0.003 | E41: кошторис під ключ 27.10
A42: Коефіцієнт митної вартості (доставка до кордону, страхування) | B42: =4840.7596950824/4234.64192 -> 1.1431332 | E42: кошторис під ключ 27.10: мито 4 840,76 $ / сума FOB × ставки
...

Sheet Стрінги
A1: Стрінги і MPPT інвертора Deye SUN-100K-G03 — перевірка напруг і струмів
A2: Модуль ZNSHINE ZXN8-BD132-730: Voc 49,5 В, Vmp 41,7 В, Imp 17,51 А, Isc 18,51 А; Voc −0,25 %/K, Pmax −0,30 %/K. Інвертор: DC до 1000 В, старт 250 В, MPPT 200–850 В, 40 А і 60 А (Isc) на MPPT, 6 MPPT по 2 стрінги.
A4: Voc модуля, В | B4: 49.5
A5: Коеф. Voc, %/K | B5: -0.25
A6: Мінімальна температура модуля, °C | B6: -30
A7: Vmp при 70 °C, В | B7: 37
A8: Vmp при −10 °C, В | B8: 45.93
A9: Imp, А | B9: 17.51
A10: Isc, А | B10: 18.51
A11: Інвертор: макс. напруга DC, В | B11: 1000
A12: Інвертор: MPPT від, В | B12: 200
A13: Інвертор: MPPT до, В | B13: 850
A14: Інвертор: старт, В | B14: 250
A15: Інвертор: струм на MPPT, А | B15: 40
A16: Інвертор: Isc на MPPT, А | B16: 60
A18: Варіант | B18: Модулів у стрінгу | C18: Voc при −30 °C, В | D18: ≤ 1000 В | E18: Vmp при 70 °C, В | F18: ≥ 200 В і старт 250 В | G18: Vmp при −10 °C, В | H18: ≤ 850 В | I18: Imp на MPPT (2 стрінги), А | J18: ≤ 40 А | K18: Isc на MPPT, А | L18: ≤ 60 А
A19: «Як є» | B19: =Параметри!B13 -> 13 | C19: =B19*$B$4*(1+$B$5/100*($B$6-25)) -> 731.98125 | D19: =IF(C19<=$B$11,"так","ні") -> так | E19: =B19*$B$7 -> 481 | F19: =IF(AND(E19>=$B$12,E19>=$B$14),"так","ні") -> так | G19: =B19*$B$8 -> 597.09 | H19: =IF(G19<=$B$13,"так","ні") -> так | I19: =2*$B$9 -> 35.02 | J19: =IF(I19<=$B$15,"так","ні") -> так | K19: =2*$B$10 -> 37.02 | L19: =IF(K19<=$B$16,"так","ні") -> так
A20: «ДБН» | B20: =Параметри!C13 -> 12 | C20: =B20*$B$4*(1+$B$5/100*($B$6-25)) -> 675.675 | D20: =IF(C20<=$B$11,"так","ні") -> так | E20: =B20*$B$7 -> 444 | F20: =IF(AND(E20>=$B$12,E20>=$B$14),"так","ні") -> так | G20: =B20*$B$8 -> 551.16 | H20: =IF(G20<=$B$13,"так","ні") -> так | I20: =2*$B$9 -> 35.02 | J20: =IF(I20<=$B$15,"так","ні") -> так | K20: =2*$B$10 -> 37.02 | L20: =IF(K20<=$B$16,"так","ні") -> так
A22: Варіант | B22: Стрінг | C22: MPPT | D22: Модулів | E22: Де | F22: Грані | G22: Нахил, ° | H22: Генерація, МВт·год | I22: Втрати невідповідності, % | J22: Кабель DC «+» і «−», м
A23: «Як є» | B23: S3 | C23: 1 | D23: 13 | E23: арка | F23: схід | G23: 3 | H23: 9.314 | I23: 1.3 | J23: 66.6
A24: «Як є» | B24: S4 | C24: 1 | D24: 13 | E24: арка | F24: схід | G24: 7.1 | H24: 9.352 | I24: 1.1 | J24: 71.9
A25: «Як є» | B25: S5 | C25: 2 | D25: 13 | E25: арка | F25: схід | G25: 10.8 | H25: 9.333 | I25: 1 | J25: 77.4
A26: «Як є» | B26: S10 | C26: 2 | D26: 13 | E26: арка + нижній дах | F26: схід | G26: 13.1 | H26: 8.837 | I26: 3.7 | J26: 73.7
A27: «Як є» | B27: S2 | C27: 3 | D27: 13 | E27: арка | F27: захід | G27: 3.2 | H27: 9.259 | I27: 1.2 | J27: 68.1
A28: «Як є» | B28: S8 | C28: 3 | D28: 13 | E28: арка | F28: захід | G28: 3.6 | H28: 8.854 | I28: 5.2 | J28: 69.9
A29: «Як є» | B29: S1 | C29: 4 | D29: 13 | E29: арка | F29: захід | G29: 7.6 | H29: 9.138 | I29: 1.2 | J29: 75.2
A30: «Як є» | B30: S9 | C30: 4 | D30: 13 | E30: арка + нижній дах | F30: захід | G30: 11.6 | H30: 8.36 | I30: 4.5 | J30: 86.4
A31: «Як є» | B31: S6 | C31: 5 | D31: 13 | E31: нижній дах + надбудова | F31: захід | G31: 15 | H31: 8.064 | I31: 1.6 | J31: 37.4
A32: «Як є» | B32: S7 | C32: 5 | D32: 13 | E32: нижній дах + надбудова | F32: схід | G32: 15 | H32: 7.558 | I32: 2.7 | J32: 34.6
A33: «Як є» | B33: S11 | C33: 6 | D33: 13 | E33: нижній дах + стіни | F33: схід, південь, захід | G33: 66.9 | H33: 6.307 | I33: 11.2 | J33: 24.6
A34: Разом «Як є» | D34: =SUM(D23:D33) -> 143 | H34: =SUM(H23:H33) -> 94.376 | J34: =SUM(J23:J33) -> 685.8
A36: «ДБН» | B36: S4 | C36: 1 | D36: 12 | E36: арка | F36: схід | G36: 3.1 | H36: 8.584 | I36: 1.4 | J36: 68.1
A37: «ДБН» | B37: S9 | C37: 1 | D37: 12 | E37: арка | F37: схід | G37: 9 | H37: 8.45 | I37: 3 | J37: 82.6
A38: «ДБН» | B38: S5 | C38: 2 | D38: 12 | E38: арка | F38: схід | G38: 10.9 | H38: 8.616 | I38: 1 | J38: 77.9
A39: «ДБН» | B39: S10 | C39: 2 | D39: 12 | E39: арка + нижній дах + надбудова | F39: схід | G39: 14 | H39: 7.905 | I39: 4.3 | J39: 57.4
A40: «ДБН» | B40: S3 | C40: 3 | D40: 12 | E40: арка | F40: захід | G40: 3.1 | H40: 8.529 | I40: 1.3 | J40: 65.2
A41: «ДБН» | B41: S8 | C41: 3 | D41: 12 | E41: арка | F41: захід | G41: 4 | H41: 8.165 | I41: 5 | J41: 77.3
A42: «ДБН» | B42: S1 | C42: 4 | D42: 12 | E42: арка | F42: захід | G42: 11.4 | H42: 8.276 | I42: 1.2 | J42: 80.8
A43: «ДБН» | B43: S2 | C43: 4 | D43: 12 | E43: арка | F43: захід | G43: 7.7 | H43: 8.416 | I43: 1.3 | J43: 76.7
A44: «ДБН» | B44: S6 | C44: 5 | D44: 12 | E44: нижній дах + надбудова | F44: захід | G44: 15 | H44: 7.385 | I44: 1.6 | J44: 38.4
...
