Workbook

Sheet Кошторис
A1: Кошторис будівництва під ключ — СЕС на даху АБК, ТОВ МК «Антарес», варіант «ДБН»
A2: Turnkey construction estimate — rooftop PV plant on the administrative building, Antares LLC, DBN-compliant option
A3: Інвертор Deye SUN-100K-G03 (100 кВт, DC до 1 000 В), 132 модулів ZNSHINE 730 Вт у 11 стрінгах по 12. $ без ПДВ. / Inverter Deye SUN-100K-G03 (100 kW, DC up to 1000 V), 132 ZNSHINE 730 W modules in 11 strings of 12. USD excl. VAT.
A5: № | B5: Позиція | C5: Item | D5: Од. / Unit | E5: К-сть / Qty | F5: Ціна, $ / Price, $ | G5: Мито / Duty | H5: Сума, $ / Amount, $ | I5: Підстава / Basis
A6: 1. Закупівля в Китаї, FOB — разом із замовленням СЕС цеху | C6: 1. Purchase in China, FOB — together with the shop roof PV order
A7: 1.1 | B7: Фотомодулі ZNSHINE ZXN8-BD132-730 (730 Вт, виводи 1,2–1,4 м), з запасом 2 % | C7: PV modules ZNSHINE ZXN8-BD132-730 (730 W, leads 1.2–1.4 m), 2 % spare | D7: шт / pcs | E7: =Параметри!B10 -> 135 | F7: =Параметри!$B$31 -> 73 | G7: 0 | H7: =E7*F7 -> 9855 | I7: кошторис під ключ 27.10 / turnkey estimate 27.10, поз. 1.2
A8: 1.2 | B8: Кріплення на арці «Лага 0°»: лаги 41×41, гільзи з муфтами, шпильки M10, крайні профілі, кутники, притиски, метизи | C8: Arch mounting "Rail 0°": 41×41 rails, sleeves with couplings, M10 rods, edge profiles, angles, clamps, fasteners | D8: модуль / module | E8: =Параметри!B5 -> 86 | F8: =Параметри!$B$32 -> 11.168831 | G8: 0.008 | H8: =E8*F8 -> 960.51948 | I8: КП 26.10, на модуль / per module
A9: 1.3 | B9: Кріплення 15° на нижньому даху і надбудові: опори «доміку» і трикутники під одиночні модулі, П-кронштейни, діагоналі, притиски, метизи | C9: 15° mounting on lower roof and stair house: dual-tilt supports and triangles for single modules, U-brackets, diagonals, clamps, fasteners | D9: модуль / module | E9: =Параметри!B6+Параметри!B7 -> 37 | F9: =Параметри!$B$33 -> 10.897619 | G9: 0.008 | H9: =E9*F9 -> 403.2119 | I9: ГалКат 15° 22.10, на модуль / per module
A10: 1.4 | B10: Кріплення на південних стінах: рейки 41×41×2,5, кронштейни з анкерами, притиски, трос безпеки | C10: South wall mounting: 41×41×2.5 rails, brackets with anchors, clamps, safety rope | D10: модуль / module | E10: =Параметри!B8 -> 9 | F10: =Параметри!$B$34 -> 8.6026936 | G10: 0.008 | H10: =E10*F10 -> 77.424242 | I10: кошторис під ключ 27.10 / turnkey estimate 27.10, поз. 1.3.2
A11: 1.5 | B11: Кабелі DC H1Z2Z2-K 1×6 мм², роз'єми MC4, металорукав, стяжки, бирки | C11: DC cables H1Z2Z2-K 1×6 mm², MC4 connectors, conduit, ties, labels | D11: стрінг / string | E11: =Параметри!B12 -> 11 | F11: =Параметри!$B$35 -> 60 | G11: 0.067 | H11: =E11*F11 -> 660 | I11: кошторис під ключ 27.10 / turnkey estimate 27.10, поз. 1.4
A12: 1.6 | B12: Лотки 100×50 з кришками, фасонні, опори, кронштейни, з'єднувачі | C12: Trays 100×50 with lids, fittings, supports, brackets, couplers | D12: стрінг / string | E12: =Параметри!B12 -> 11 | F12: =Параметри!$B$36 -> 64.572917 | G12: 0.001 | H12: =E12*F12 -> 710.30208 | I12: кошторис під ключ 27.10 / turnkey estimate 27.10, поз. 1.7
A13: 1.7 | B13: Блискавкозахист і вирівнювання потенціалів: ПЗІП RS485, провідники 1×6 і 1×16, затискачі, контактні шайби | C13: Lightning protection and bonding: RS485 SPD, 1×6 and 1×16 conductors, clamps, contact washers | D13: модуль / module | E13: =Параметри!B9 -> 132 | F13: =Параметри!$B$37 -> 1.1363636 | G13: 0.05 | H13: =E13*F13 -> 150 | I13: кошторис під ключ 27.10 / turnkey estimate 27.10, поз. 1.8
A14: 1.8 | B14: Кабель RS485 2×2×0,75 в екрані — лічильник → інвертор | C14: RS485 cable 2×2×0.75 screened — meter to inverter | D14: м / m | E14: =Параметри!B18 -> 55 | F14: =Параметри!$B$38 -> 0.26285714 | G14: 0.1 | H14: =E14*F14 -> 14.457143 | I14: специфікація Китай 26.10 / China spec
B15: Разом закупівля в Китаї | C15: Total purchase in China | H15: =SUM(H7:H14) -> 12830.915
A16: 2. Наша комісія — супровід замовлення за договором комісії | C16: 2. Our commission — order support under commission agreement
A17: 2.1 | B17: Комісія від закупівлі в Китаї | C17: Commission on China purchase | F17: =Параметри!$B$39 -> 0.05 | H17: =H15*F17 -> 641.54574 | I17: договір комісії / agreement
B18: Разом комісія | C18: Total commission | H18: =H17 -> 641.54574
A19: 3. Доставка до об'єкта, страхування, мито | C19: 3. Delivery to site, insurance, customs duty
A20: 3.1 | B20: Доставка модулів у контейнерах 40'HQ | C20: Module freight in 40'HQ containers | D20: шт / pcs | E20: =Параметри!B10 -> 135 | F20: =Параметри!$B$40 -> 11.784512 | H20: =E20*F20 -> 1590.9091 | I20: кошторис під ключ 27.10 / turnkey estimate 27.10, поз. 3.2
A21: 3.2 | B21: Доставка кріплення, кабелів і лотків | C21: Freight of mounting, cables and trays | D21: модуль / module | E21: =Параметри!B9 -> 132 | F21: =Параметри!$B$41 -> 6.6287879 | H21: =E21*F21 -> 875 | I21: кошторис під ключ 27.10 / turnkey estimate 27.10, поз. 3.3
A22: 3.3 | B22: Страхування вантажу, крім модулів | C22: Cargo insurance, except modules | F22: =Параметри!$B$42 -> 0.003 | H22: =(H15-H7)*F22 -> 8.9277446 | I22: кошторис під ключ 27.10 / turnkey estimate 27.10
A23: 3.4 | B23: Мито на товари, крім модулів (модулі — пільга «245») | C23: Customs duty except modules (modules — "245" exemption) | F23: =Параметри!$B$43 -> 1.1431332 | H23: =SUMPRODUCT(G7:G14,H7:H14)*F23 -> 74.766925 | I23: ставки за кодами УКТ ЗЕД / tariff rates
B24: Разом доставка і мито | C24: Total delivery and duty | H24: =SUM(H20:H23) -> 2549.6038
A25: 4. Купуємо в Україні: інвертор, підключення, баласт, безпека покрівлі | C25: 4. Purchased in Ukraine: inverter, connection, ballast, roof safety
A26: 4.1 | B26: Інвертор мережевий Deye SUN-100K-G03: 100 кВт, 3 фази 400 В, 6 MPPT, DC до 1 000 В, IP65; DC-роз'єднувач, ПЗІП тип II на DC і AC | C26: Grid inverter Deye SUN-100K-G03: 100 kW, 3-phase 400 V, 6 MPPT, DC up to 1000 V, IP65; DC switch, type II SPD on DC and AC | D26: шт / pcs | E26: 1 | F26: =Параметри!$B$58/(1+Параметри!$B$54)/Параметри!$B$29 -> 2595.7711 | H26: =E26*F26 -> 2595.7711 | I26: 220volt.com.ua, 28.10.2026, у наявності
A27: 4.2 | B27: Баластний блок 300×300×60 з муфтою: під лаги, опори «доміку» і трикутники — з матом, під крайні профілі арки — без мата; опори лотків (+1 %) | C27: Ballast block 300×300×60 with coupling: under rails, dual-tilt supports and triangles — with mat, under arch edge profiles — without mat; tray supports (+1 %) | D27: шт / pcs | E27: =Параметри!B16 -> 684 | F27: =Параметри!$B$44 -> 3 | H27: =E27*F27 -> 2052 | I27: рішення власника 26.10 / owner decision
A28: 4.3 | B28: Кабель ВВГнг 5×70 мм², мідь — інвертор → щит СЕС біля вступного щита АБК | C28: Cable VVGng 5×70 mm² copper — inverter to PV board at the building main board | D28: м / m | E28: =Параметри!B17 -> 45 | F28: =Параметри!$B$59/(1+Параметри!$B$54)/Параметри!$B$29 -> 59.854459 | H28: =E28*F28 -> 2693.4507 | I28: amperia.com.ua, 28.10.2026, у наявності
A29: 4.4 | B29: Щит СЕС: автоматичний вимикач ABB A2B 250 TMF 200 (3P, 200 А) у корпусі IP54 | C29: PV board: MCCB ABB A2B 250 TMF 200 (3P, 200 A) in IP54 enclosure | D29: компл / set | E29: 1 | F29: =Параметри!$B$60/(1+Параметри!$B$54)/Параметри!$B$29+Параметри!$B$61/(1+Параметри!$B$54)/Параметри!$B$29 -> 296.62917 | H29: =E29*F29 -> 296.62917 | I29: electroelan.dp.ua, 28.10.2026; 220volt.com.ua, 28.10.2026
A30: 4.5 | B30: ПЗІП AC тип 2, 4P (Eaton SPCT2-280/4) у щиті СЕС | C30: AC surge protector type 2, 4P (Eaton SPCT2-280/4) in PV board | D30: шт / pcs | E30: 1 | F30: =Параметри!$B$66/(1+Параметри!$B$54)/Параметри!$B$29 -> 123.8702 | H30: =E30*F30 -> 123.8702 | I30: 001.com.ua, 28.10.2026
A31: 4.6 | B31: Лічильник CHINT DTSU666 з трансформаторами струму 250 А — обмеження видачі в мережу (Zero Export) | C31: Meter CHINT DTSU666 with 250 A CTs — export limiting (Zero Export) | D31: компл / set | E31: 1 | F31: =Параметри!$B$62/(1+Параметри!$B$54)/Параметри!$B$29 -> 131.72941 | H31: =E31*F31 -> 131.72941 | I31: hotline.ua (Технопоставка), 28.10.2026
A32: 4.7 | B32: Доставка матеріалів України на об'єкт | C32: Delivery of Ukrainian materials to site | D32: блок / block | E32: =Параметри!B16 -> 684 | F32: =Параметри!$B$47 -> 0.33836518 | H32: =E32*F32 -> 231.44179 | I32: кошторис під ключ 27.10 / turnkey estimate 27.10, поз. 4.9
A33: 4.8 | B33: Драбина П1 на арку з поручнями над парапетом | C33: Fixed ladder P1 to the arch with handrails above parapet | D33: м / m | E33: =Параметри!B19 -> 5.8 | F33: =Параметри!$B$63/(1+Параметри!$B$54)/Параметри!$B$29 -> 167.07507 | H33: =E33*F33 -> 969.03542 | I33: flagma.ua (ПП «Ліга», Київ), 28.10.2026
A34: 4.9 | B34: Площадка з огорожею 0,6 м на арці перед виходом на покрівлю | C34: Landing with 0.6 m guard on the arch at the roof exit | D34: шт / pcs | E34: =Параметри!B20 -> 1 | F34: 0 | H34: =E34*F34 -> 0 | I34: ціна — за КП виробника драбини / price per ladder maker quote
A35: 4.10 | B35: Драбини П1 на надбудову сходів (2 шт.) | C35: Fixed ladders P1 to the stair house (2 pcs) | D35: м / m | E35: =Параметри!B21 -> 5.6 | F35: =Параметри!$B$63/(1+Параметри!$B$54)/Параметри!$B$29 -> 167.07507 | H35: =E35*F35 -> 935.62041 | I35: flagma.ua (ПП «Ліга», Київ), 28.10.2026
A36: 4.11 | B36: Огородження покрівлі 0,6 м, металеве | C36: Roof guardrail 0.6 m, steel | D36: м / m | E36: =Параметри!B22 -> 99 | F36: =Параметри!$B$64/(1+Параметри!$B$54)/Параметри!$B$29 -> 13.324237 | H36: =E36*F36 -> 1319.0995 | I36: prom.ua (Профі Фасад), 28.10.2026
A37: 4.12 | B37: Ходові доріжки 0,8 м — гумові плити 500×500×20 мм | C37: Walkways 0.8 m — rubber tiles 500×500×20 mm | D37: м² / m² | E37: =Параметри!B23 -> 63 | F37: =Параметри!$B$65/(1+Параметри!$B$54)/Параметри!$B$29 -> 20.234648 | H37: =E37*F37 -> 1274.7828 | I37: reziplit.in.ua, 28.10.2026
A38: 4.13 | B38: Анкер від сповзання на арці, до основи покрівлі, з герметизацією | C38: Anti-slide anchor on the arch, to the roof deck, with sealing | D38: шт / pcs | E38: =Параметри!B25 -> 10 | F38: =Параметри!$B$57 -> 44.99 | H38: =E38*F38 -> 449.9 | I38: кошторис СЕС і УЗЕ 26.10 / estimate 26.10
B39: Разом купуємо в Україні | C39: Total purchased in Ukraine | H39: =SUM(H26:H38) -> 13073.33
A40: 5. Роботи | C40: 5. Works
A41: 5.1 | B41: Встановлення і наладка СЕС, електромонтажні роботи DC і AC, налаштування Zero Export, вимірювання | C41: PV installation and commissioning, DC and AC electrical works, Zero Export set-up, measurements | D41: кВтп / kWp | E41: =Параметри!B11 -> 96.36 | F41: =Параметри!$B$48 -> 50 | H41: =E41*F41 -> 4818 | I41: рішення власника 26.10 / owner decision
...

Sheet Специфікація
A1: Специфікація СЕС АБК, варіант «ДБН» / Bill of materials, admin building PV, DBN option
A2: Кількості — з 3D-моделі АБК і розрахунку стрінгів; ціни — у кошторисі за рядком. / Quantities from the 3D model and string design; prices in the estimate line shown.
A4: № | B4: Позиція | C4: Item | D4: Од. / Unit | E4: К-сть / Qty | F4: Рядок кошторису / Estimate line | G4: Як пораховано / Basis
A5: A. Фотомодулі | C5: PV modules
A6: A1 | B6: Фотомодуль ZNSHINE ZXN8-BD132-730, 730 Вт, 2 384 × 1 303 × 33 мм, виводи 1,2–1,4 м | C6: PV module ZNSHINE ZXN8-BD132-730, 730 W, 2384 × 1303 × 33 mm, leads 1.2–1.4 m | D6: шт / pcs | E6: 135 | F6: 1.1 | G6: 132 у стрінгах (арка 86, нижній дах 31, надбудова 6, стіни 9) + 2 % / 132 in strings + 2 %
A7: B. Кріплення на арці — «Лага 0°»: лаги на баласті, шпилькова тяга, крайні профілі | C7: Arch roof mounting — "Rail 0°": rails on ballast, rod ties, edge profiles
A8: B1 | B8: Лага 41×41×1,5 перфорована оцинкована, 4 800 мм (бічні отвори Ø10,5 через 100, від торців 50) | C8: Rail 41×41×1.5 perforated galvanised, 4800 mm (side holes Ø10.5 at 100, 50 from ends) | D8: шт / pcs | E8: 37 | F8: 1.2 | G8: 35 — 2 комірки на шматок; лаги 251,6 м / 2 cells per piece
A9: B2 | B9: Лага 41×41×1,5 перфорована оцинкована, 2 400 мм | C9: Rail 41×41×1.5 perforated galvanised, 2400 mm | D9: шт / pcs | E9: 37 | F9: 1.2 | G9: 35 — непарна комірка / odd cell
A10: B3 | B10: Гільза П 45,5×35×2, 200 мм, з привареною муфтою M10×50 (ліва / права різьба) | C10: U-sleeve 45.5×35×2, 200 mm, with welded M10×50 coupling (LH / RH thread) | D10: шт / pcs | E10: 62 | F10: 1.2 | G10: 60: на кожній лазі в лінії тяги, на стиках лаг / on every rail of a tie line, at rail splices
A11: B4 | B11: Болт M10×60 + 2 шайби DIN 125 + гайка + трубка 14×1,75×38 (гільза до лаги) | C11: Bolt M10×60 + 2 washers DIN 125 + nut + tube 14×1.75×38 (sleeve to rail) | D11: компл / set | E11: 126 | F11: 1.2 | G11: 2 на гільзу: 120 / 2 per sleeve
A12: B5 | B12: Шпилька M10 права / ліва різьба, 1 299 мм | C12: Threaded rod M10 RH / LH, 1299 mm | D12: шт / pcs | E12: 54 | F12: 1.2 | G12: 48 між модулями в колонці + 3 через прохід / between modules + across passage
A13: B6 | B13: Гайка M10 права (контргайки шпильок) | C13: Nut M10 RH (rod lock nuts) | D13: шт / pcs | E13: 108 | F13: 1.2 | G13: 2 на шпильку / 2 per rod
A14: B7 | B14: Гайка M10 ліва | C14: Nut M10 LH | D14: шт / pcs | E14: 54 | F14: 1.2 | G14: 1 на шпильку / 1 per rod
A15: B8 | B15: Профіль 41×41×1,5 крайній, 1 263 мм | C15: Edge profile 41×41×1.5, 1263 mm | D15: шт / pcs | E15: 85 | F15: 1.2 | G15: 76 на кінцях колонок + 6 через прохід / column ends + across passage
A16: B9 | B16: Кутник 160/150, t = 8, оцинкований (правий і лівий порівну) | C16: Angle bracket 160/150, t = 8, galvanised (equal RH and LH) | D16: шт / pcs | E16: 169 | F16: 1.2 | G16: 2 на профіль / 2 per profile
A17: B10 | B17: Болт M10×70 + гайка + шайби (кутник до лаги) | C17: Bolt M10×70 + nut + washers (angle to rail) | D17: компл / set | E17: 104 | F17: 1.2 | G17: 99: один на точку лаги / one per rail point
A18: B11 | B18: Болт M10×60 + гайка + шайби (кутник до профілю) | C18: Bolt M10×60 + nut + washers (angle to profile) | D18: компл / set | E18: 345 | F18: 1.2 | G18: 2 на кутник / 2 per angle
A19: B12 | B19: Притиск середній під раму 33 мм, Al, з болтом M8×60 DIN 912 A2 і гайкою з пружиною | C19: Mid clamp for 33 mm frame, Al, with M8×60 DIN 912 A2 bolt and spring nut | D19: шт / pcs | E19: 212 | F19: 1.2 | G19: 201: 3 на довгий бік на спільній лазі / 3 per long side on a shared rail
... A22: B15 | B22: Анкер від сповзання до основи покрівлі, з герметизацією | C22: Anti-slide anchor to the roof deck, with sealing | D22: шт / pcs | E22: 10 | F22: 4.13 | G22: 10: ланцюжок тяг лінії не переходить гребінь — анкер на верхній лазі (правило КМ даху цеху) / tie chain does not cross the ridge
A23: C. Кріплення 15° — «домік» і трикутники під одиночні модулі (нижній дах і надбудова) | C23: 15° mounting — dual-tilt and triangles for single modules (lower roof and stair house)
A24: C1 | B24: Лага «доміку» 41×41×1,5, 2 750 мм | C24: Dual-tilt rail 41×41×1.5, 2750 mm | D24: шт / pcs | E24: 29 | F24: 1.3 | G24: 28 опор: 14 доміків × 2 / supports: domes × 2
A25: C2 | B25: Балка 41×41×1,5, 1 450 мм (отвори шарніра і вершини — заводські) | C25: Beam 41×41×1.5, 1450 mm (hinge and apex holes factory) | D25: шт / pcs | E25: 58 | F25: 1.3 | G25: 2 на опору / 2 per support
A26: C3 | B26: Стійка 41×41×1,5, 365 мм | C26: Strut 41×41×1.5, 365 mm | D26: шт / pcs | E26: 29 | F26: 1.3 | G26: 1 на опору / 1 per support
A27: C4 | B27: П-кронштейн, нерж. 304, t = 3 | C27: U-bracket, stainless 304, t = 3 | D27: шт / pcs | E27: 29 | F27: 1.3 | G27: 1 на опору / 1 per support
A28: C5 | B28: Болти M10 опори (2 × M10×100 шарніри, M10×140 вершина, M10×65 стійка, M10×60 кронштейн) + шайби + фланцеві гайки | C28: Support bolts M10 (2 × M10×100 hinges, M10×140 apex, M10×65 strut, M10×60 bracket) + washers + flange nuts | D28: компл / set | E28: 147 | F28: 1.3 | G28: 5 на опору / 5 per support
A29: C6 | B29: Діагональ 41×41×1,5, 1 100 мм + 2 болти M10×20 з фланцевими гайками | C29: Diagonal 41×41×1.5, 1100 mm + 2 bolts M10×20 with flange nuts | D29: шт / pcs | E29: 10 | F29: 1.3 | G29: між сусідніми доміками ряду / between adjacent domes in a row
A30: C7 | B30: Притиск крайній під раму 33 мм з болтом M8 і гайкою з пружиною | C30: End clamp for 33 mm frame with M8 bolt and spring nut | D30: шт / pcs | E30: 118 | F30: 1.3 | G30: 4 на панель: 112 / 4 per panel
A31: C8 | B31: Болт M8×20 + шайба DIN 9021 (лага до муфти блока) | C31: Bolt M8×20 + washer DIN 9021 (rail to block coupling) | D31: компл / set | E31: 118 | F31: 1.3 | G31: 4 на опору / 4 per support
A32: C9 | B32: Лага трикутника 15° 41×41×1,5, 1 550 мм | C32: 15° triangle rail 41×41×1.5, 1550 mm | D32: шт / pcs | E32: 19 | F32: 1.3 | G32: 18 трикутників: 9 модулів × 2 / triangles: modules × 2
A33: C10 | B33: Балка 41×41×1,5, 1 419 мм | C33: Beam 41×41×1.5, 1419 mm | D33: шт / pcs | E33: 19 | F33: 1.3 | G33: 1 на трикутник / 1 per triangle
A34: C11 | B34: Стійка 41×41×1,5, 448 мм (13-й отвір від шарніра) | C34: Strut 41×41×1.5, 448 mm (13th hole from hinge) | D34: шт / pcs | E34: 19 | F34: 1.3 | G34: 1 на трикутник / 1 per triangle
A35: C12 | B35: П-кронштейн під 15°, нерж. 304 (зміщений отвір під болт балки) | C35: U-bracket for 15°, stainless 304 (shifted beam bolt hole) | D35: шт / pcs | E35: 19 | F35: 1.3 | G35: 1 на трикутник / 1 per triangle
... A39: C16 | B39: Болт M8×20 + шайба DIN 9021 (лага до муфти блока) | C39: Bolt M8×20 + washer DIN 9021 (rail to block coupling) | D39: компл / set | E39: 38 | F39: 1.3 | G39: 2 на трикутник / 2 per triangle
A40: D. Кріплення на південних стінах — фасадні вузли | C40: South wall mounting — facade nodes
A41: D1 | B41: Рейка 41×41×2,5 оцинкована на стіні, у розмір | C41: Wall rail 41×41×2.5 galvanised, cut to size | D41: м / m | E41: 25.2 | F41: 1.4 | G41: 8 рейок, 24,5 м: на 540 мм від торців модуля / 8 rails at 540 mm from module ends
A42: D2 | B42: Кронштейн L 60×60×5 з пазом, цинк + анкер M10 + болт M10×35 з гайкою і 2 шайбами | C42: Bracket L 60×60×5 slotted, galvanised + M10 anchor + M10×35 bolt with nut and 2 washers | D42: компл / set | E42: 30 | F42: 1.4 | G42: 28: через ≈1,2 м на спільній рейці, 2 на рейку альбомного / every ≈1.2 m
A43: D3 | B43: Притиск крайній 80 мм, Al 6005-T6, під раму 33 + болт M8 і гайка з пружиною | C43: End clamp 80 mm, Al 6005-T6, for 33 mm frame + M8 bolt and spring nut | D43: шт / pcs | E43: 17 | F43: 1.4 | G43: 16
A44: D4 | B44: Притиск середній 80 мм, Al 6005-T6 + болт M8 і гайка з пружиною | C44: Mid clamp 80 mm, Al 6005-T6 + M8 bolt and spring nut | D44: шт / pcs | E44: 11 | F44: 1.4 | G44: 10: між модулями групи, на кожній рейці / between modules, on each rail
A45: D5 | B45: Пластина заземлювальна під притиск | C45: Earthing plate under clamp | D45: шт / pcs | E45: 9 | F45: 1.4 | G45: 1 на модуль / 1 per module
A46: D6 | B46: Трос безпеки Ø3 AISI 316 у ПВХ ≈0,6 м з коушем, 2 втулками, гайкою-вушком M8 і болтом | C46: Safety rope Ø3 AISI 316 in PVC ≈0.6 m with thimble, 2 ferrules, M8 eye nut and bolt | D46: компл / set | E46: 9 | F46: 1.4 | G46: 1 на модуль, крізь заводський отвір рами / 1 per module through factory frame hole
...

Sheet Стрінги
A1: Стрінги і MPPT інвертора Deye SUN-100K-G03 / Strings and MPPT of the Deye SUN-100K-G03 inverter
A2: Модуль: Voc 49,5 В, Vmp 41,7 В, Imp 17,51 А, Isc 18,51 А, Voc −0,25 %/K. Інвертор: DC до 1 000 В, старт 250 В, MPPT 200–850 В, 40 А (Isc 60 А) на MPPT. / Module and inverter limits.
A4: Voc модуля, В / Module Voc, V | B4: 49.5
A5: Коеф. Voc, %/K / Voc coefficient, %/K | B5: -0.25
A6: Мінімальна температура модуля, °C / Min. module temp., °C | B6: -30
A7: Vmp при 70 °C, В / Vmp at 70 °C, V | B7: 37
A8: Vmp при −10 °C, В / Vmp at −10 °C, V | B8: 45.93
A9: Imp, А | B9: 17.51
A10: Isc, А | B10: 18.51
A11: Інвертор: макс. DC, В / Inverter max DC, V | B11: 1000
A12: Інвертор: MPPT від, В / MPPT min, V | B12: 200
A13: Інвертор: MPPT до, В / MPPT max, V | B13: 850
A14: Інвертор: старт, В / Start-up, V | B14: 250
A15: Інвертор: струм на MPPT, А / Current per MPPT, A | B15: 40
A16: Інвертор: Isc на MPPT, А / Isc per MPPT, A | B16: 60
A18: Перевірка / Check | B18: Модулів у стрінгу / Modules | C18: Voc −30 °C, В | D18: ≤ 1 000 В | E18: Vmp 70 °C, В | F18: ≥ 250 В | G18: Vmp −10 °C, В | H18: ≤ 850 В | I18: Imp на MPPT, А | J18: ≤ 40 А | K18: Isc на MPPT, А | L18: ≤ 60 А
A19: «ДБН» / DBN | B19: =Параметри!B13 -> 12 | C19: =B19*$B$4*(1+$B$5/100*($B$6-25)) -> 675.675 | D19: =IF(C19<=$B$11,"так / yes","ні / no") -> так / yes | E19: =B19*$B$7 -> 444 | F19: =IF(AND(E19>=$B$12,E19>=$B$14),"так / yes","ні / no") -> так / yes | G19: =B19*$B$8 -> 551.16 | H19: =IF(G19<=$B$13,"так / yes","ні / no") -> так / yes | I19: =2*$B$9 -> 35.02 | J19: =IF(I19<=$B$15,"так / yes","ні / no") -> так / yes | K19: =2*$B$10 -> 37.02 | L19: =IF(K19<=$B$16,"так / yes","ні / no") -> так / yes
A21: Стрінг / String | B21: MPPT | C21: Модулів / Modules | D21: Де / Where | E21: Грані / Faces | F21: Нахил, ° / Tilt | G21: МВт·год / MWh | H21: Невідповідність, % / Mismatch | I21: DC «+», м | J21: DC «−», м | K21: Перемички, м / Jumpers | L21: Не працює, модуле-год / Bypassed, module-h
A22: S4 | B22: 1 | C22: 12 | D22: арка / arch | E22: схід / E | F22: 3.1 | G22: 8.584 | H22: 1.4 | I22: 36.1 | J22: 36.9 | K22: 14.8 | L22: 1928
A23: S9 | B23: 1 | C23: 12 | D23: арка / arch | E23: схід / E | F23: 9 | G23: 8.45 | H23: 3 | I23: 37 | J23: 30.6 | K23: 27.6 | L23: 2021
A24: S5 | B24: 2 | C24: 12 | D24: арка / arch | E24: схід / E | F24: 10.9 | G24: 8.616 | H24: 1 | I24: 36.3 | J24: 38.2 | K24: 3.9 | L24: 522
A25: S10 | B25: 2 | C25: 12 | D25: арка / arch + нижній дах / lower roof + надбудова / stair house | E25: схід / E | F25: 14 | G25: 7.905 | H25: 4.3 | I25: 39.4 | J25: 10.7 | K25: 71.3 | L25: 5703
A26: S3 | B26: 3 | C26: 12 | D26: арка / arch | E26: захід / W | F26: 3.1 | G26: 8.529 | H26: 1.3 | I26: 36.3 | J26: 34.8 | K26: 10 | L26: 2302
A27: S8 | B27: 3 | C27: 12 | D27: арка / arch | E27: захід / W | F27: 4 | G27: 8.165 | H27: 5 | I27: 45.4 | J27: 20 | K27: 24.2 | L27: 3410
A28: S1 | B28: 4 | C28: 12 | D28: арка / arch | E28: захід / W | F28: 11.4 | G28: 8.276 | H28: 1.2 | I28: 46.2 | J28: 39.9 | K28: 6.8 | L28: 1185
A29: S2 | B29: 4 | C29: 12 | D29: арка / arch | E29: захід / W | F29: 7.7 | G29: 8.416 | H29: 1.3 | I29: 43.6 | J29: 28.8 | K29: 2.6 | L29: 2097
A30: S6 | B30: 5 | C30: 12 | D30: нижній дах / lower roof + надбудова / stair house | E30: захід / W | F30: 15 | G30: 7.385 | H30: 1.6 | I30: 24.5 | J30: 17.4 | K30: 36.1 | L30: 4485
A31: S7 | B31: 5 | C31: 12 | D31: нижній дах / lower roof + надбудова / stair house | E31: схід / E | F31: 15 | G31: 6.855 | H31: 2.8 | I31: 23.1 | J31: 16.1 | K31: 33.7 | L31: 5573
A32: S11 | B32: 6 | C32: 12 | D32: нижній дах / lower roof + надбудова / stair house + стіни / walls | E32: схід / E, південь / S, захід / W | F32: 71.2 | G32: 5.914 | H32: 10.4 | I32: 19.8 | J32: 11.9 | K32: 69.2 | L32: 7875
A33: Разом / Total | C33: =SUM(C22:C32) -> 132 | G33: =SUM(G22:G32) -> 87.095 | I33: =SUM(I22:I32) -> 387.7 | J33: =SUM(J22:J32) -> 285.3 | K33: =SUM(K22:K32) -> 300.2 | L33: =SUM(L22:L32) -> 37101
A35: Не працює — модуль обходиться байпас-діодом, бо його струм нижчий за робочий струм стрінга (часткова тінь або інша орієнтація), за ясного неба, години на рік; стрінг працює, поки в роботі ≥ 6 модулів (MPPT від 200 В). / Bypassed — the module current is below the string operating current (partial shade or different orientation), clear sky, hours per year.

Sheet Параметри
A1: Параметри кошторису СЕС АБК, варіант «ДБН» / Estimate parameters, admin building PV, DBN option
A2: Синій — вихідні дані, чорний — формули. $ без ПДВ. / Blue — inputs, black — formulas. USD excl. VAT.
A4: Параметр / Parameter | B4: Значення / Value | C4: Од. / Unit | D4: Джерело / Source
A5: Модулів на арці / Modules on the arch roof | B5: 86 | C5: шт | D5: 3D-модель АБК, варіант «ДБН» / 3D model
A6: Модулів на нижньому даху, «домік» 15° / Modules on the lower roof, dual-tilt 15° | B6: 31 | C6: шт | D6: 33 місця, 2 поза стрінгами / 33 places, 2 outside strings
A7: Модулів на надбудові сходів, «домік» 15° / Modules on the stair house, dual-tilt 15° | B7: 6 | C7: шт | D7: 3D-модель АБК / 3D model
A8: Модулів на південних стінах / Modules on south walls | B8: 9 | C8: шт | D8: 3D-модель АБК / 3D model
A9: Модулів у стрінгах / Modules in strings | B9: =B5+B6+B7+B8 -> 132 | C9: шт
A10: Модулів до поставки (+2 %) / Modules to supply (+2 %) | B10: =ROUNDUP(B9*$B$30,0) -> 135 | C10: шт | D10: кошторис під ключ 27.10 / turnkey estimate 27.10
A11: Потужність СЕС, DC / PV capacity, DC | B11: =B9*$B$28/1000 -> 96.36 | C11: кВтп / kWp | D11: 730 Вт × модулів / 730 W × modules
A12: Стрінгів / Strings | B12: 11 | C12: шт | D12: по 2 на MPPT, 6 MPPT / 2 per MPPT, 6 MPPT
A13: Модулів у стрінгу / Modules per string | B13: 12 | C13: шт | D13: Voc при −30 °C ≤ 1 000 В / Voc at −30 °C ≤ 1000 V
A14: Генерація модулів за рік (DC) / Annual module yield (DC) | B14: 87.1 | C14: МВт·год / MWh | D14: повна модель K1: Meteonorm 8.1, тіні DSM, байпас-діоди / full K1 model
A15: Блоків під опори лотків / Blocks under tray supports | B15: 65 | C15: шт | D15: лотки на даху 96.6 м, опора через 1,5 м / roof trays, support every 1.5 m
A16: Баластних блоків до замовлення (+1 %) / Ballast blocks to order (+1 %) | B16: =ROUNDUP(($B$45+B15)*1.01,0) -> 684 | C16: шт | D16: кріплення модулів — 3D-модель (кожен блок), опори лотків / module mounting — 3D model (every block), tray supports
A17: Кабель AC інвертор → щит СЕС / AC cable inverter → PV board | B17: 45 | C17: м | D17: по стіні і стояку сходів, + 10 % / along wall and stair riser, + 10 %
A18: Кабель RS485 лічильник → інвертор / RS485 cable meter → inverter | B18: 55 | C18: м | D18: уздовж кабелю AC / along AC cable
A19: Драбина П1 на арку: 4,8 + 1,0 м / Fixed ladder P1 to arch: 4.8 + 1.0 m | B19: 5.8 | C19: м | D19: ДБН В.1.1-7:2016 п. 8.8–8.10
A20: Площадка з огорожею 0,6 м на арці / Landing with 0.6 m guard on arch | B20: 1 | C20: шт | D20: ДБН В.1.1-7:2016 табл. 5
A21: Драбини П1 на надбудову / Fixed ladders P1 to stair house | B21: 5.6 | C21: м | D21: 2,25 + 1,0 і 1,35 + 1,0 м; ДБН В.1.1-7:2016 п. 8.8
A22: Огородження покрівлі 0,6 м / Roof guardrail 0.6 m | B22: 99 | C22: м | D22: ДБН В.1.1-7:2016 п. 8.12; ДБН В.2.6-220:2017 п. 6.1.2
A23: Ходові доріжки 0,8 м / Walkways 0.8 m | B23: 63 | C23: м² | D23: ДБН В.2.6-220:2017 п. 7.1.3
A24: Монтаж драбин, площадки, огородження і доріжок / Installation of ladders, landing, guardrail, walkways | B24: 112 | C24: люд.·год / man-h | D24: драбини 2 × 16, огородження 64, доріжки 16 / ladders 2 × 16, guardrail 64, walkways 16
A25: Анкерів від сповзання на арці / Anti-slide anchors on the arch | B25: 10 | C25: шт | D25: ланцюжок тяг лінії не переходить гребінь — анкер на верхній лазі (правило КМ даху цеху) / tie chain not crossing the ridge
A27: Ставки і ціни / Rates and prices | B27: Значення / Value | C27: Од. / Unit | D27: Джерело / Source
A28: Потужність модуля / Module power | B28: 730 | C28: Вт / W | D28: паспорт ZNSHINE / datasheet
A29: Курс / Exchange rate | B29: 44.89 | C29: грн/$ | D29: як у кошторисі 27.10 / as estimate 27.10
A30: Запас модулів / Module spare | B30: 1.02 | D30: кошторис під ключ 27.10 / turnkey estimate 27.10
A31: Фотомодуль ZNSHINE ZXN8-BD132-730, FOB / PV module, FOB | B31: 73 | C31: $/шт | D31: КП ES-261026-01
A32: Кріплення по даху на баласті, на модуль / Roof rail mounting on ballast, per module | B32: =21500/1925 -> 11.168831 | C32: $/модуль | D32: КП 26.10: 21 500 $ на 1 925 модулів / quote 26.10
A33: Кріплення «домік» 15°, на модуль / Dual-tilt 15° mounting, per module | B33: =11211/1260+4*0.5 -> 10.897619 | C33: $/модуль | D33: ГалКат 15° 22.10 + 4 притиски по 0,50 $ / GalKat 15° + 4 clamps
A34: Кріплення на стіні, на модуль / Wall mounting, per module | B34: =2555/297 -> 8.6026936 | C34: $/модуль | D34: кошторис під ключ 27.10 / turnkey estimate 27.10, поз. 1.3.2
A35: Кабелі DC, MC4, металорукав, на стрінг / DC cables, MC4, conduit, per string | B35: =11520/192 -> 60 | C35: $/стрінг | D35: кошторис під ключ 27.10 / turnkey estimate 27.10, поз. 1.4
A36: Лотки, фасонні, кріплення, на стрінг / Trays, fittings, supports, per string | B36: =12398/192 -> 64.572917 | C36: $/стрінг | D36: кошторис під ключ 27.10 / turnkey estimate 27.10, поз. 1.7
A37: Блискавкозахист: ПЗІП, провідники, затискачі, на модуль / Lightning protection, per module | B37: =2400/2112 -> 1.1363636 | C37: $/модуль | D37: кошторис під ключ 27.10 / turnkey estimate 27.10, поз. 1.8
A38: Кабель RS485 2×2×0,75 в екрані, FOB / RS485 cable, FOB | B38: =276/1050 -> 0.26285714 | C38: $/м | D38: специфікація Китай 26.10 / China spec 26.10
A39: Наша комісія від закупівлі в Китаї / Our commission on China purchase | B39: 0.05 | D39: договір комісії / commission agreement
A40: Доставка модулів, 40'HQ / 594 модулі / Module freight per module | B40: =7000/594 -> 11.784512 | C40: $/шт | D40: кошторис під ключ 27.10 / turnkey estimate 27.10, поз. 3.2
A41: Доставка решти вантажу, на модуль / Other freight per module | B41: =14000/2112 -> 6.6287879 | C41: $/модуль | D41: кошторис під ключ 27.10 / turnkey estimate 27.10, поз. 3.3
A42: Страхування вантажу, крім модулів / Cargo insurance except modules | B42: 0.003 | D42: кошторис під ключ 27.10 / turnkey estimate 27.10
...
