Workbook

Sheet Кошторис
A1: Кошторис будівництва під ключ — СЕС і УЗЕ 3 × Golen LES-H20, ТОВ МК «Антарес»: дах цеху + модулі на місці ліхтарів + склад (перерахунок 27.10.2026)
A2: $ без ПДВ. Основа — кошторис 26.10 «варіант 1» (1 925 модулів); колонка «Було 26.10» — для порівняння. Синій — вихідні дані, чорний — формули, зелений — з інших аркушів.
A4: № | B4: Позиція | C4: Од. | D4: К-сть | E4: Ціна, $ | F4: Мито | G4: Сума, $ | H4: Було 26.10, $ | I4: Підстава
A5: 1. Закупівля в Китаї, FOB (на основі КП ES-261026-01)
A6: 1.1 | B6: Накопичувачі Golen LES-H20-1205W500C-PS, 3 × 190 000 | C6: компл | D6: 1 | E6: 570000 | F6: 0 | G6: =D6*E6 -> 570000 | H6: 570000 | I6: пільга «245»: 0 %, без ПДВ. Перевірити в Golen допустиму потужність PV на контейнер: було 468, стане 514 кВтп
A7: 1.2 | B7: Фотомодулі ZNSHINE ZXN8-BD132-730, з виводами 1,2–1,4 м | C7: шт | D7: =Параметри!$B$10 -> 2155 | E7: 73 | F7: 0 | G7: =D7*E7 -> 157315 | H7: 143372 | I7: модулі × 1,02; 73 $ (КП 26.10); пільга «245»
A8: 1.3.1 | B8: Кріплення даху цеху і складу: лаги, гільзи, шпильки, профілі, кутники, притиски, метизи | C8: компл | D8: 1 | E8: =ROUND(21500*(Параметри!$B$5+Параметри!$B$7)/Параметри!$B$11,0) -> 20271 | F8: 0.008 | G8: =D8*E8 -> 20271 | H8: 21500 | I8: КП 26.10 21 500 $ пропорційно модулям даху і складу (1 815 / 1 925)
A9: 1.3.2 | B9: Кріплення на місці ліхтарів: рейки, притиски, кронштейни | C9: компл | D9: 1 | E9: =Ліхтарі!H11 -> 2555 | F9: 0.008 | G9: =D9*E9 -> 2555 | H9: 0 | I9: аркуш «Ліхтарі»
A10: 1.4 | B10: Кабелі DC 1×6, MC4, подовжувачі, металорукав | C10: компл | D10: 1 | E10: =ROUND(10500*Параметри!$B$13/Параметри!$B$14,0) -> 11520 | F10: 0.067 | G10: =D10*E10 -> 11520 | H10: 10500 | I10: КП 26.10 пропорційно стрінгам (192 / 175)
A11: 1.5 | B11: Щити PV 7/1 (робочі + 1 запасний), шафи вводу ШВ — 3, RS485 | C11: компл | D11: 1 | E11: =14500+(Параметри!$B$15-Параметри!$B$16)*Параметри!$B$17*1.02 -> 16282.96 | F11: 0.052 | G11: =D11*E11 -> 16282.96 | H11: 14500 | I11: КП 26.10 + щити на ліхтарях (1 на ліхтар)
A12: 1.6 | B12: Лінії Al 120/185/240, Cu 50, наконечники | C12: компл | D12: 1 | E12: =ROUND(26328*Параметри!$B$15/Параметри!$B$16,0) -> 30378 | F12: 0.069 | G12: =D12*E12 -> 30378 | H12: 26328 | I12: КП 26.10 пропорційно робочим щитам (30 / 26); траси від торців ліхтарів — уточнити
A13: 1.7 | B13: Лотки, кришки, фасонні, траверси, кріплення | C13: компл | D13: 1 | E13: =ROUND(11300*Параметри!$B$13/Параметри!$B$14,0) -> 12398 | F13: 0.001 | G13: =D13*E13 -> 12398 | H13: 11300 | I13: КП 26.10 пропорційно стрінгам
A14: 1.8 | B14: Блискавкозахист: ПЗІП, провідники, затискачі | C14: компл | D14: 1 | E14: 2400 | F14: 0.05 | G14: =D14*E14 -> 2400 | H14: 2400 | I14: КП 26.10; каркаси на ліхтарях приєднати до мережі БЗ
A15: 1.9 | B15: Підключення УЗЕ: шафи ЩР-УЗЕ(AC), наконечники AC, заземлення, зв'язок | C15: компл | D15: 1 | E15: 4100 | F15: 0.05 | G15: =D15*E15 -> 4100 | H15: 4100 | I15: КП 26.10
B16: Разом закупівля в Китаї | G16: =G6+G7+G8+G9+G10+G11+G12+G13+G14+G15 -> 827219.96 | H16: =H6+H7+H8+H9+H10+H11+H12+H13+H14+H15 -> 804000
A18: 2. Наша комісія — супровід замовлення за договором комісії
A19: 2.1 | B19: Комісія від закупівлі в Китаї | D19: =Параметри!$B$25 -> 0.05 | G19: =G16*Параметри!$B$25 -> 41360.998 | H19: 40200 | I19: 5 %: 70 % одразу, 30 % після прибуття
B20: Разом комісія | G20: =G19 -> 41360.998 | H20: =H19 -> 40200
A22: 3. Доставка до об'єкта, страхування, митне оформлення, мито
A23: 3.1 | B23: Контейнери УЗЕ Golen: море, авто, страхування, митне оформлення | C23: конт. | D23: =Параметри!$B$21 -> 3 | E23: =Параметри!$B$22 -> 15000 | G23: =D23*E23 -> 45000 | H23: 45000 | I23: по 15 000 $
A24: 3.2 | B24: Контейнери 40'HQ з модулями | C24: конт. | D24: =ROUNDUP(Параметри!$B$10/Параметри!$B$18,0) -> 4 | E24: =Параметри!$B$20 -> 7000 | G24: =D24*E24 -> 28000 | H24: 28000 | I24: модулі по 594 у 40'HQ
A25: 3.3 | B25: Контейнери 40'HQ з кріпленням, кабелями, щитами, лотками | C25: конт. | D25: =Параметри!$B$19 -> 2 | E25: =Параметри!$B$20 -> 7000 | G25: =D25*E25 -> 14000 | H25: 14000 | I25: 33,7 т, 90 м³ (26.10); рейки ліхтарів ≈1 т — вміщаються
A26: 3.4 | B26: Страхування вантажу, крім УЗЕ | D26: =Параметри!$B$23 -> 0.003 | G26: =(G16-G6)*Параметри!$B$23 -> 771.65988 | H26: 702 | I26: від вартості товару
A27: 3.5 | B27: Митний брокер, декларації | C27: компл | D27: 1 | E27: =Параметри!$B$24 -> 240 | G27: =D27*E27 -> 240 | H27: 240
A28: 3.6 | B28: Мито на товари, крім модулів і УЗЕ (пільга «245») | G28: =(G8*F8+G9*F9+G10*F10+G11*F11+G12*F12+G13*F13+G14*F14+G15*F15)*(1+((Параметри!$B$19*Параметри!$B$20)+(G8+G9+G10+G11+G12+G13+G14+G15)*Параметри!$B$23)/(G8+G9+G10+G11+G12+G13+G14+G15)) -> 4840.7597 | H28: 4378 | I28: ставки за кодами УКТ ЗЕД; база — митна вартість з доставкою
B29: Разом доставка і мито | G29: =G23+G24+G25+G26+G27+G28 -> 92852.42 | H29: =H23+H24+H25+H26+H27+H28 -> 92320
A31: 4. Купуємо в Україні
A32: 4.1 | B32: Баластний блок 300×300×60 з муфтою і матом — під лаги і кінці лаг | C32: шт | D32: =ROUND(4756*Параметри!$B$5/Параметри!$B$12,0) -> 4457 | I32: Том 3 КМ (4 756 на 1 749 модулів даху) пропорційно модулям даху
A33: 4.2 | B33: Баластний блок — під крайні профілі | C33: шт | D33: =ROUND(848*Параметри!$B$5/Параметри!$B$12,0) -> 795 | I33: те саме
A34: 4.3 | B34: Баластний блок — опори лотків | C34: шт | D34: 821 | I34: Том 3 КМ
A35: 4.4 | B35: Баластний блок — рами щитів PV на даху (23 × 4) | C35: шт | D35: 92 | I35: щити на ліхтарях — на каркасі, без баласту
A36: 4.5 | B36: Баластні блоки до замовлення, +1 % | C36: шт | D36: =ROUNDUP(SUM(D32:D35)*1.01,0) -> 6227 | E36: =Параметри!$B$26 -> 3 | G36: =D36*E36 -> 18681 | H36: 19749 | I36: 3 $ за блок
A37: 4.6 | B37: Кабель ВВГнг 1×120 мм², мідь — AC контейнери → ТП-5913 | C37: м | D37: 2536.38 | E37: 21.75 | G37: =D37*E37 -> 55166.265 | H37: 55166 | I37: Том 8: 2 305,8 м + 10 %
A38: 4.7 | B38: Кабель ВВГнг 1×95 мм², мідь — N і PE | C38: м | D38: 845.46 | E38: 17.22 | G38: =D38*E38 -> 14558.821 | H38: 14559 | I38: Том 8: 768,6 м + 10 %
A39: 4.8 | B39: Анкер від сповзання вздовж ліхтарів | C39: шт | D39: 194 | E39: 44.99 | G39: =D39*E39 -> 8728.06 | H39: 8728 | I39: Том 3 КМ; SikaRoof Anchor 250
A40: 4.9 | B40: Доставка матеріалів України на об'єкт | C40: компл | D40: 1 | E40: =ROUND(2227.7*D36/6583,0) -> 2107 | G40: =D40*E40 -> 2107 | H40: 2228 | I40: кошторис 26.10 пропорційно блокам
B41: Разом купуємо в Україні | G41: =G36+G37+G38+G39+G40 -> 99241.146 | H41: =H36+H37+H38+H39+H40 -> 100430
A43: 5. Роботи, фундаменти, EMS
A44: 5.1 | B44: Встановлення і наладка СЕС, електромонтажні роботи DC і AC | C44: кВтп | D44: =Параметри!$B$9 -> 1541.76 | E44: =Параметри!$B$27 -> 50 | G44: =D44*E44 -> 77088 | H44: 70263 | I44: 50 $/кВт
A45: 5.2 | B45: Механізація: автокран і автовишка | C45: компл | D45: 1 | E45: =ROUND(2807*Параметри!$B$8/Параметри!$B$11,0) -> 3080 | G45: =D45*E45 -> 3080 | H45: 2807 | I45: кошторис 26.10 пропорційно модулям
...

Sheet Параметри
A1: Параметри кошторису — перерахунок 27.10.2026
A2: Синій — вихідні дані (можна змінювати), чорний — формули, жовте тло — потрібна ціна або замір. $ без ПДВ.
A4: Параметр | B4: Значення | C4: Од. | D4: Джерело
A5: Модулів на даху цеху (варіант А, v3) | B5: 1639 | C5: шт | D5: розкладка даху за картою опромінення 27.10 (149 стрінгів)
A6: Модулів на місці ліхтарів (вертикально, каркас ≈13°) | B6: 297 | C6: шт | D6: розкладка 27.10, 20:26 (27 стрінги, зручно для монтажу)
A7: Модулів на даху складу | B7: 176 | C7: шт | D7: кошторис 26.10 (склад 176)
A8: Модулів разом | B8: =B5+B6+B7 -> 2112 | C8: шт
A9: Потужність СЕС | B9: =B8*0.73 -> 1541.76 | C9: кВтп | D9: 730 Вт × модулів
A10: Модулів до поставки (+2 %) | B10: =ROUNDUP(B8*1.02,0) -> 2155 | C10: шт | D10: запас як у КП 26.10
A11: Модулів у кошторисі 26.10 | B11: 1925 | C11: шт | D11: дах 1 749 + склад 176
A12: Модулів даху в кошторисі 26.10 | B12: 1749 | C12: шт | D12: кошторис 26.10
A13: Стрінгів разом | B13: =149+27+16 -> 192 | C13: шт | D13: дах 149 + ліхтарі 27 + склад 16
A14: Стрінгів у кошторисі 26.10 | B14: 175 | C14: шт | D14: 1 925 / 11
A15: Щитів PV 7/1 робочих | B15: 30 | C15: шт | D15: дах і склад 26 (як 26.10) + по 1 на кожен ліхтар (6–7 стрінгів біля торця)
A16: Щитів PV 7/1 робочих у кошторисі 26.10 | B16: 26 | C16: шт | D16: КП 26.10: 26 + 1 запасний
A17: Щит PV 7/1 + рама | B17: 437 | C17: $ | D17: КП 26.10: щит 420 + рама 17
A18: Модулів у контейнері 40'HQ | B18: 594 | C18: шт | D18: паспорт ZNSHINE
A19: Контейнерів 40'HQ з іншим вантажем | B19: 2 | C19: шт | D19: кошторис 26.10: 33,7 т, 90 м³
A20: Доставка 40'HQ Шанхай → Київ, на об'єкт | B20: 7000 | C20: $ | D20: кошторис 26.10
A21: Контейнерів УЗЕ Golen | B21: 3 | C21: шт | D21: КП ES-261026-01
A22: Доставка контейнера УЗЕ | B22: 15000 | C22: $ | D22: рішення власника 26.10
A23: Страхування вантажу (крім УЗЕ) | B23: 0.003 | D23: від вартості товару
A24: Митний брокер, декларації | B24: 240 | C24: $ | D24: кошторис 26.10
A25: Наша комісія від закупівлі в Китаї | B25: 0.05 | D25: договір комісії
A26: Баластний блок з муфтою і матом | B26: 3 | C26: $ | D26: рішення власника 26.10
A27: Роботи: встановлення і наладка СЕС, електромонтаж | B27: 50 | C27: $/кВт | D27: рішення власника 26.10
A28: EMS об'єкта (E-Systems) | B28: 25000 | C28: $ | D28: рішення власника
A29: Запас, від собівартості | B29: 0.04 | D29: рішення власника 26.10
A30: Винагорода генпідрядника, від собівартості (без запасу) | B30: 0.18 | D30: рішення власника 26.10
A31: ПДВ | B31: 0.2 | D31: ПКУ, ст. 193
A32: Нова покрівля над прорізами ліхтарів | B32: 674 | C32: м² | D32: проліт каркаса 3,1 м (зі слів власника), 13°, без торців — виміряти
A33: Розбирання скління ліхтарів + нова покрівля прорізу | B33: 0 | C33: $/м² | D33: немає в даних — вписати ціну

Sheet Ліхтарі
A1: Кріплення модулів на місці ліхтарів — кількості за розкладкою 27.10 (вертикально, 2 рейки на схил)
A2: Рейки — в зоні притисків ZNSHINE (540 мм від торців модуля); ціни — КП 26.10 (профіль 41×41 — 1,35 $/м, притиск — 0,50 $); кронштейн — оцінка.
A4: № | B4: Позиція | C4: Од. | D4: За розкладкою | E4: Запас | F4: До замовлення | G4: Ціна, $ | H4: Сума, $ | I4: Підстава
A5: Л.1 | B5: Рейка — профіль 41×41, уздовж ліхтаря, по 2 на схил | C5: м | D5: 789.9 | E5: 0.05 | F5: =ROUNDUP(D5*(1+E5),0) -> 830 | G5: 1.35 | H5: =F5*G5 -> 1120.5 | I5: 16 рейок; ряд модулів + 0,1 м з кожного кінця
A6: Л.2 | B6: Притиск середній Al 6005-T6 (спільний на 2 модулі) | C6: шт | D6: 578 | E6: 0.03 | F6: =ROUNDUP(D6*(1+E6),0) -> 596 | G6: 0.5 | H6: =F6*G6 -> 298 | I6: 2 рейки × (модулів у ряду − 1)
A7: Л.3 | B7: Притиск кінцевий Al 6005-T6 | C7: шт | D7: 32 | E7: 0.03 | F7: =ROUNDUP(D7*(1+E7),0) -> 33 | G7: 0.5 | H7: =F7*G7 -> 16.5 | I7: 2 рейки × 2 кінці ряду
A8: Л.4 | B8: Кронштейн рейки до балки каркаса (кутник з болтами) | C8: шт | D8: =ROUNDUP(D5/D9,0)+16 -> 543 | E8: 0.03 | F8: =ROUNDUP(D8*(1+E8),0) -> 560 | G8: 2 | H8: =F8*G8 -> 1120 | I8: крок кронштейнів — за кроком поперечних балок (виміряти); ціна — оцінка
A9: Л.5 | B9: Крок кронштейнів уздовж рейки (для Л.4) | C9: м | D9: 1.5 | I9: прийнято до замірів каркаса
B11: Разом кріплення на ліхтарях | H11: =SUM(H5:H8) -> 2555
B13: Не входить: розбирання скління, нова покрівля прорізу (Параметри), підсилення каркаса — за перевіркою КМ.

Sheet Специфікація — зміни
A1: Специфікація замовлення в Китаї — що змінюється проти 26.10 (1 925 модулів, 117 позицій)
A2: Повна специфікація 26.10 — у файлі «Специфікація_замовлення_в_Китаї_Антарес_Б_1925_модулів». Тут — позиції, що змінюються; решта — без змін. Пропорційні — до оновлення КМ і ЕП.
A4: Позиція | B4: Од. | C4: Було 26.10 | D4: Стає | E4: Як пораховано | F4: Уточнити
A5: Модулі ZNSHINE ZXN8-BD132-730, виводи 1,2–1,4 м | B5: шт | C5: 1964 | D5: =Параметри!$B$10 -> 2155 | E5: 2 112 × 1,02 | F5: доплата за виводи — Golen
A6: Щит PV 7/1 | B6: шт | C6: 27 | D6: =Параметри!$B$15+1 -> 31 | E6: дах і склад 26 + ліхтарі 4 (по 1 на ліхтар) + 1 запасний | F6: місце щита біля торця ліхтаря
A7: MC4 на корпусах щитів | B7: пар | C7: 189 | D7: =(Параметри!$B$15+1)*7 -> 217 | E7: 7 на щит
A8: MC4 на кабелях | B8: пар | C8: 595 | D8: =ROUNDUP(595*Параметри!$B$13/Параметри!$B$14,0) -> 653 | E8: пропорційно стрінгам
A9: Кабель 1×6 мм² (червоний / чорний) | B9: м | C9: 4 500 / 5 000 | D9: =TEXT(CEILING(4500*Параметри!$B$13/Параметри!$B$14,500),"# ##0")&" / "&TEXT(CEILING(5000*Параметри!$B$13/Параметри!$B$14,500),"# ##0") -> 5 000 / 5 500 | E9: пропорційно стрінгам, барабани по 500 м | F9: траси від торців ліхтарів до щитів
A10: Металорукав | B10: м | C10: 850 | D10: =CEILING(850*Параметри!$B$13/Параметри!$B$14,50) -> 950 | E10: пропорційно стрінгам
A11: Лінії Al 120 / 185 / 240 мм² | B11: м | C11: 942 / 3 214 / 3 532 | D11: =TEXT(ROUND(942*Параметри!$B$15/Параметри!$B$16,0),"# ##0")&" / "&TEXT(ROUND(3214*Параметри!$B$15/Параметри!$B$16,0),"# ##0")&" / "&TEXT(ROUND(3532*Параметри!$B$15/Параметри!$B$16,0),"# ##0") -> 1 087 / 3 708 / 4 075 | E11: пропорційно робочим щитам 30 / 26 | F11: траси 4 нових ліній — у ЕП
A12: Гільзи лаг | B12: шт | C12: 1990 | D12: =ROUND(1990*Параметри!$B$5/Параметри!$B$12,0) -> 1865 | E12: пропорційно модулям даху 1 639 / 1 749 | F12: КМ
A13: Шпильки M10 права / ліва різьба | B13: шт | C13: 1715 | D13: =ROUND(1715*Параметри!$B$5/Параметри!$B$12,0) -> 1607 | E13: те саме | F13: КМ
A14: Кутники 150 мм | B14: шт | C14: 936 | D14: =ROUND(936*Параметри!$B$5/Параметри!$B$12,0) -> 877 | E14: те саме | F14: КМ
A15: НОВЕ: рейка 41×41 на ліхтарях | B15: м | C15: 0 | D15: =Ліхтарі!F5 -> 830 | E15: аркуш «Ліхтарі» | F15: профіль і переріз — у КМ
A16: НОВЕ: притиск середній Al 6005-T6 | B16: шт | C16: 0 | D16: =Ліхтарі!F6 -> 596 | E16: аркуш «Ліхтарі»
A17: НОВЕ: притиск кінцевий Al 6005-T6 | B17: шт | C17: 0 | D17: =Ліхтарі!F7 -> 33 | E17: аркуш «Ліхтарі»
A18: НОВЕ: кронштейн рейки до балки каркаса | B18: шт | C18: 0 | D18: =Ліхтарі!F8 -> 560 | E18: крок 1,5 м (прийнято) | F18: крок балок каркаса — виміряти
A19: Баластні блоки (Україна) | B19: шт | C19: 6583 | D19: =Кошторис!D36 -> 6227 | E19: дах пропорційно модулям, ліхтарі без баласту
